


  <!-- chassis -->

  <link name="base_link"/>

  <joint name="chassis" type="fixed">
    <parent link="base_link"/>
    <child link="link_chassis"/>
    <origin xyz="0 0 0.01" rpy="0 0 0"/>
  </joint>

  <link name="link_chassis">
    <inertial>
      <origin xyz="0 0 0" rpy="0 0 0"/>
      <mass value="0.005" />
      <inertia ixx="0.001" ixy="0.0" ixz="0.0"
               iyy="0.001" iyz="0.0"
               izz="0.001" />
    </inertial>

    <collision name="collision_chassis">
      <origin xyz="0 0 0" rpy="0 0 0"/>
      <geometry>
        <box size="${chassis_x} ${chassis_y} ${chassis_z}"/>
      </geometry>
    </collision>

    <visual>
      <origin rpy="0 0 0" xyz="0 0 0"/>
      <geometry>
        <box size="${chassis_x} ${chassis_y} ${chassis_z}"/>
      </geometry>
      <material name="white"/>
    </visual>
  </link>

<!-- left wheel -->

    <joint name="left_wheel_joint" type="continuous">
        <origin xyz="0.25 -0.2 -0.2" rpy="0 1.57 0"/>
        <parent link="link_chassis"/>
        <child link="left_wheel"/>
        <axis xyz="0 0 1"/>
        <limit effort="10000" velocity="1000"/>
        <joint_properties damping="1.0" friction="1.0"/>
    </joint>

    <link name="left_wheel">
        <!-- <xacro:inertial_matrix/> -->
        <inertial>
          <mass value="2.8498940e-02" />
          <origin xyz="0 0 0" rpy="0 0 0"/>
          <inertia ixx="1.1175580e-05" ixy="-4.2369783e-11" ixz="-5.9381719e-09"
                  iyy="1.1192413e-05" iyz="-1.4400107e-11"
                  izz="2.0712558e-05" />
        </inertial>

        <collision name="link_right_wheel_collision">
            <origin xyz="0 0 0" rpy="0 0 0"/>
            <geometry>
                <cylinder length="${wheel}" radius="${wheel_radius}"/>
            </geometry>
        </collision>
        <visual name="left_wheel_visual">
            <origin xyz="0 0 0" rpy="0 0 0"/>
            <geometry>
                <cylinder length="${wheel}" radius="${wheel_radius}"/>
            </geometry>
            <material name="black"/>
        </visual>
    </link>

<!-- right wheel -->
    <joint name="right_wheel_joint" type="continuous">
        <origin xyz="-0.25 -0.2 -0.2" rpy="0 1.57 0"/>
        <parent link="link_chassis"/>
        <child link="right_wheel"/>
        <axis xyz="0 0 1"/>
        <limit effort="10000" velocity="1000"/>
        <joint_properties damping="1.0" friction="1.0"/>
    </joint>

    <link name="right_wheel">
        <!-- <xacro:inertial_matrix /> -->
        <inertial>
          <mass value="2.8498940e-02" />
          <origin xyz="0 0 0" rpy="0 0 0"/>
          <inertia ixx="1.1175580e-05" ixy="-4.2369783e-11" ixz="-5.9381719e-09"
                  iyy="1.1192413e-05" iyz="-1.4400107e-11"
                  izz="2.0712558e-05" />
        </inertial>
        <collision name="link_right_wheel_collision">
            <origin xyz="0 0 0" rpy="0 0 0"/>
            <geometry>
                <cylinder length="${wheel}" radius="${wheel_radius}"/>
            </geometry>
        </collision>
        <visual name="right_wheel_visual">
            <origin xyz="0 0 0" rpy="0 0 0"/>
            <geometry>
                <cylinder length="${wheel}" radius="${wheel_radius}"/>
            </geometry>
            <material name="black"/>
        </visual>
    </link>

<!-- caster left wheel -->

    <joint name="caster_left_wheel_joint" type="fixed">
        <origin xyz="0.25 0.2 -0.2" rpy="0 1.57 0"/>
        <parent link="link_chassis"/>
        <child link="caster_left_wheel"/>
        <!-- <axis xyz="0 0 1"/> -->
        <!-- <limit effort="10000" velocity="1000"/>
        <joint_properties damping="1.0" friction="1.0"/> -->
    </joint>

    <link name="caster_left_wheel">
        <!-- <xacro:inertial_matrix/> -->
        <inertial>
          <mass value="2.8498940e-02" />
          <origin xyz="0 0 0" rpy="0 0 0"/>
          <inertia ixx="1.1175580e-05" ixy="-4.2369783e-11" ixz="-5.9381719e-09"
                  iyy="1.1192413e-05" iyz="-1.4400107e-11"
                  izz="2.0712558e-05" />
        </inertial>
        <collision name="link_caster_left_wheel">
            <origin xyz="0 0 0" rpy="0 0 0"/>
            <geometry>
                <cylinder length="${wheel}" radius="${wheel_radius}"/>
            </geometry>
        </collision>
        <visual name="caster_left_wheel_visual">
            <origin xyz="0 0 0" rpy="0 0 0"/>
            <geometry>
                <cylinder length="${wheel}" radius="${wheel_radius}"/>
            </geometry>
            <material name="black"/>
        </visual>
    </link>

<!-- caster right wheel -->

    <joint name="caster_right_wheel_joint" type="fixed">
        <origin xyz="-0.25 0.2 -0.2" rpy="0 1.57 0"/>
        <parent link="link_chassis"/>
        <child link="caster_right_wheel"/>
        <!-- <axis xyz="0 0 1"/> -->
        <!-- <limit effort="10000" velocity="1000"/>
        <joint_properties damping="1.0" friction="1.0"/> -->
    </joint>

    <link name="caster_right_wheel">
        <!-- <xacro:inertial_matrix/> -->
        <inertial>
          <mass value="2.8498940e-02" />
          <origin xyz="0 0 0" rpy="0 0 0"/>
          <inertia ixx="1.1175580e-05" ixy="-4.2369783e-11" ixz="-5.9381719e-09"
                  iyy="1.1192413e-05" iyz="-1.4400107e-11"
                  izz="2.0712558e-05" />
        </inertial>
        <collision name="caster_link_right_wheel">
            <origin xyz="0 0 0" rpy="0 0 0"/>
            <geometry>
                <cylinder length="${wheel}" radius="${wheel_radius}"/>
            </geometry>
        </collision>
        <visual name="caster_right_wheel_visual">
            <origin xyz="0 0 0" rpy="0 0 0"/>
            <geometry>
                <cylinder length="${wheel}" radius="${wheel_radius}"/>
            </geometry>
            <material name="black"/>
        </visual>
    </link>

</robot>
